[2025-03-15 12:21:21,657: INFO: main: Welcome to our custom logging data science]
[2025-03-15 14:24:17,247: INFO: common: yaml file: config\config.yaml loaded successfully]
[2025-03-15 14:24:17,253: INFO: common: yaml file: params.yaml loaded successfully]
[2025-03-15 14:25:03,035: INFO: common: yaml file: config\config.yaml loaded successfully]
[2025-03-15 14:25:03,040: INFO: common: yaml file: params.yaml loaded successfully]
[2025-03-15 14:25:32,029: INFO: common: yaml file: config\config.yaml loaded successfully]
[2025-03-15 14:25:32,032: INFO: common: yaml file: params.yaml loaded successfully]
[2025-03-15 14:25:32,033: INFO: common: yaml file: schema.yaml loaded successfully]
[2025-03-15 14:25:32,039: INFO: common: created directory at: artifacts]
[2025-03-15 14:25:32,043: INFO: common: created directory at: artifacts/data_ingestion]
[2025-03-15 14:27:13,705: INFO: common: yaml file: config\config.yaml loaded successfully]
[2025-03-15 14:27:13,710: INFO: common: yaml file: params.yaml loaded successfully]
[2025-03-15 14:27:13,715: INFO: common: yaml file: schema.yaml loaded successfully]
[2025-03-15 14:27:13,717: INFO: common: created directory at: artifacts]
[2025-03-15 14:27:13,721: INFO: common: created directory at: artifacts/data_ingestion]
[2025-03-15 14:28:14,764: INFO: common: yaml file: config\config.yaml loaded successfully]
[2025-03-15 14:28:14,768: INFO: common: yaml file: params.yaml loaded successfully]
[2025-03-15 14:28:14,772: INFO: common: yaml file: schema.yaml loaded successfully]
[2025-03-15 14:28:14,772: INFO: common: created directory at: artifacts]
[2025-03-15 14:28:14,779: INFO: common: created directory at: artifacts/data_ingestion]
[2025-03-15 14:29:39,959: INFO: 3182789448: artifacts/data_ingestion/data.zip download! with following info: 
Connection: close
Content-Length: 23329
Cache-Control: max-age=300
Content-Security-Policy: default-src 'none'; style-src 'unsafe-inline'; sandbox
Content-Type: application/zip
ETag: "c69888a4ae59bc5a893392785a938ccd4937981c06ba8a9d6a21aa52b4ab5b6e"
Strict-Transport-Security: max-age=31536000
X-Content-Type-Options: nosniff
X-Frame-Options: deny
X-XSS-Protection: 1; mode=block
X-GitHub-Request-Id: 4EFE:216C75:626D7:111BA8:67D5417B
Accept-Ranges: bytes
Date: Sat, 15 Mar 2025 08:59:39 GMT
Via: 1.1 varnish
X-Served-By: cache-hyd1100027-HYD
X-Cache: MISS
X-Cache-Hits: 0
X-Timer: S1742029179.303017,VS0,VE265
Vary: Authorization,Accept-Encoding,Origin
Access-Control-Allow-Origin: *
Cross-Origin-Resource-Policy: cross-origin
X-Fastly-Request-ID: c690d4eec92bd241789386b4048bba1c8a192036
Expires: Sat, 15 Mar 2025 09:04:39 GMT
Source-Age: 0

]
[2025-03-15 14:33:15,346: INFO: common: yaml file: config\config.yaml loaded successfully]
[2025-03-15 14:33:15,352: INFO: common: yaml file: params.yaml loaded successfully]
[2025-03-15 14:33:15,359: INFO: common: yaml file: schema.yaml loaded successfully]
[2025-03-15 14:33:15,362: INFO: common: created directory at: artifacts]
[2025-03-15 14:33:15,362: INFO: common: created directory at: artifacts/data_ingestion]
[2025-03-15 14:33:15,367: INFO: 3182789448: File already exists]
[2025-03-15 17:56:31,595: INFO: main: >>>>> stage Data Ingestion Stage started <<<<]
[2025-03-15 17:56:31,599: INFO: common: yaml file: config\config.yaml loaded successfully]
[2025-03-15 17:56:31,599: INFO: common: yaml file: params.yaml loaded successfully]
[2025-03-15 17:56:31,601: INFO: common: yaml file: schema.yaml loaded successfully]
[2025-03-15 17:56:31,602: ERROR: main: "'ConfigBox' object has no attribute 'artifacts_root'"]
Traceback (most recent call last):
  File "box\\box.py", line 594, in box.box.Box.__getitem__
KeyError: 'artifacts_root'

The above exception was the direct cause of the following exception:

Traceback (most recent call last):
  File "box\\box.py", line 633, in box.box.Box.__getattr__
  File "box\\box.py", line 621, in box.box.Box.__getitem__
box.exceptions.BoxKeyError: "'artifacts_root'"

During handling of the above exception, another exception occurred:

Traceback (most recent call last):
  File "box\\box.py", line 635, in box.box.Box.__getattr__
AttributeError: 'ConfigBox' object has no attribute 'artifacts_root'

The above exception was the direct cause of the following exception:

Traceback (most recent call last):
  File "box\\config_box.py", line 29, in box.config_box.ConfigBox.__getattr__
  File "box\\box.py", line 649, in box.box.Box.__getattr__
box.exceptions.BoxKeyError: "'ConfigBox' object has no attribute 'artifacts_root'"

During handling of the above exception, another exception occurred:

Traceback (most recent call last):
  File "box\\box.py", line 594, in box.box.Box.__getitem__
KeyError: 'artifacts_root'

The above exception was the direct cause of the following exception:

Traceback (most recent call last):
  File "box\\box.py", line 633, in box.box.Box.__getattr__
  File "box\\box.py", line 621, in box.box.Box.__getitem__
box.exceptions.BoxKeyError: "'artifacts_root'"

During handling of the above exception, another exception occurred:

Traceback (most recent call last):
  File "box\\box.py", line 635, in box.box.Box.__getattr__
AttributeError: 'ConfigBox' object has no attribute 'artifacts_root'

The above exception was the direct cause of the following exception:

Traceback (most recent call last):
  File "E:\DataScienceProject1\main.py", line 9, in <module>
    data_ingestion.initiate_data_ingestion()
  File "E:\DataScienceProject1\src\datascience\pipeline\data_ingestion_pipeline.py", line 12, in initiate_data_ingestion
    config=ConfigurationManager()
  File "E:\DataScienceProject1\src\datascience\config\configuration.py", line 15, in __init__
    create_directories([self.config.artifacts_root])
  File "box\\config_box.py", line 31, in box.config_box.ConfigBox.__getattr__
  File "box\\box.py", line 649, in box.box.Box.__getattr__
box.exceptions.BoxKeyError: "'ConfigBox' object has no attribute 'artifacts_root'"
[2025-03-15 18:03:20,016: INFO: main: >>>>>> stage Data Ingestion stage started <<<<<<]
[2025-03-15 18:03:20,019: INFO: common: yaml file: config\config.yaml loaded successfully]
[2025-03-15 18:03:20,019: INFO: common: yaml file: params.yaml loaded successfully]
[2025-03-15 18:03:20,022: INFO: common: yaml file: schema.yaml loaded successfully]
[2025-03-15 18:03:20,022: ERROR: main: "'ConfigBox' object has no attribute 'artifacts_root'"]
Traceback (most recent call last):
  File "box\\box.py", line 594, in box.box.Box.__getitem__
KeyError: 'artifacts_root'

The above exception was the direct cause of the following exception:

Traceback (most recent call last):
  File "box\\box.py", line 633, in box.box.Box.__getattr__
  File "box\\box.py", line 621, in box.box.Box.__getitem__
box.exceptions.BoxKeyError: "'artifacts_root'"

During handling of the above exception, another exception occurred:

Traceback (most recent call last):
  File "box\\box.py", line 635, in box.box.Box.__getattr__
AttributeError: 'ConfigBox' object has no attribute 'artifacts_root'

The above exception was the direct cause of the following exception:

Traceback (most recent call last):
  File "box\\config_box.py", line 29, in box.config_box.ConfigBox.__getattr__
  File "box\\box.py", line 649, in box.box.Box.__getattr__
box.exceptions.BoxKeyError: "'ConfigBox' object has no attribute 'artifacts_root'"

During handling of the above exception, another exception occurred:

Traceback (most recent call last):
  File "box\\box.py", line 594, in box.box.Box.__getitem__
KeyError: 'artifacts_root'

The above exception was the direct cause of the following exception:

Traceback (most recent call last):
  File "box\\box.py", line 633, in box.box.Box.__getattr__
  File "box\\box.py", line 621, in box.box.Box.__getitem__
box.exceptions.BoxKeyError: "'artifacts_root'"

During handling of the above exception, another exception occurred:

Traceback (most recent call last):
  File "box\\box.py", line 635, in box.box.Box.__getattr__
AttributeError: 'ConfigBox' object has no attribute 'artifacts_root'

The above exception was the direct cause of the following exception:

Traceback (most recent call last):
  File "E:\DataScienceProject1\main.py", line 9, in <module>
    data_ingestion.initiate_data_ingestion()
  File "E:\DataScienceProject1\src\datascience\pipeline\data_ingestion_pipeline.py", line 12, in initiate_data_ingestion
    config=ConfigurationManager()
  File "E:\DataScienceProject1\src\datascience\config\configuration.py", line 15, in __init__
    create_directories([self.config.artifacts_root])
  File "box\\config_box.py", line 31, in box.config_box.ConfigBox.__getattr__
  File "box\\box.py", line 649, in box.box.Box.__getattr__
box.exceptions.BoxKeyError: "'ConfigBox' object has no attribute 'artifacts_root'"
[2025-03-15 18:32:58,638: INFO: main: >>>>>> stage Data Ingestion stage started <<<<<<]
[2025-03-15 18:32:58,643: INFO: common: yaml file: config\config.yaml loaded successfully]
[2025-03-15 18:32:58,643: INFO: common: yaml file: params.yaml loaded successfully]
[2025-03-15 18:32:58,643: INFO: common: yaml file: schema.yaml loaded successfully]
[2025-03-15 18:32:58,643: INFO: common: created directory at: artifacts]
[2025-03-15 18:32:58,643: INFO: common: created directory at: artifacts/data_ingestion]
[2025-03-15 18:34:24,131: INFO: data_ingestion: artifacts/data_ingestion/data.zip download! with following info: 
Connection: close
Content-Length: 23329
Cache-Control: max-age=300
Content-Security-Policy: default-src 'none'; style-src 'unsafe-inline'; sandbox
Content-Type: application/zip
ETag: "c69888a4ae59bc5a893392785a938ccd4937981c06ba8a9d6a21aa52b4ab5b6e"
Strict-Transport-Security: max-age=31536000
X-Content-Type-Options: nosniff
X-Frame-Options: deny
X-XSS-Protection: 1; mode=block
X-GitHub-Request-Id: 7CE1:937E5:A3815:1A8C35:67D57AD6
Accept-Ranges: bytes
Date: Sat, 15 Mar 2025 13:04:23 GMT
Via: 1.1 varnish
X-Served-By: cache-hyd1100024-HYD
X-Cache: MISS
X-Cache-Hits: 0
X-Timer: S1742043863.797567,VS0,VE562
Vary: Authorization,Accept-Encoding,Origin
Access-Control-Allow-Origin: *
Cross-Origin-Resource-Policy: cross-origin
X-Fastly-Request-ID: 6e30ac08d40f83541a093a8efd7364c832a25552
Expires: Sat, 15 Mar 2025 13:09:23 GMT
Source-Age: 0

]
[2025-03-15 18:34:24,135: INFO: main: >>>>>> stage Data Ingestion stage completed <<<<<<

x==========x]
